Workbook

Sheet Учебный план
A1: УТВЕРЖДАЮ
A2: ректор Финансового университета
A3: М. А. Эскиндаров " " 20 г
A4: УЧЕБНЫЙ ПЛАН
A5: Факультет
A6: направление подготовки: код и наименование направления подготовки, ОП "Наименование"
A9: Код и наименование блоков, содержательных модулей, дисциплин | C9: Департаменты, кафедры, партнеры | D9: Код компетенций | E9: По семестрам | H9: Текущий контроль | M9: Зачетные единицы | N9: Часов | S9: 1 курс. Распределение учебной работы студентов по семестрам и видам учебных занятий | AB9: 2 курс. Распределение учебной работы студентов по семестрам и видам учебных занятий | AK9: 3 курс. Распределение учебной работы студентов по семестрам и видам учебных занятий | AT9: 4 курс. Распределение учебной работы студентов по семестрам и видам учебных занятий
E10: Промежут аттестация | G10: Курсовая проект (работа) | N10: Всего | O10: В том числе
H11: РАР | I11: ДТЗ | J11: к/р | K11: Эссе | L11: проектная работа | O11: Аудиторных | P11: В том числе | S11: Зачетные единицы | T11: 1 семестр | X11: 2 семестр | AB11: Зачетные единицы | AC11: 3 семестр | AG11: 4 семестр | AK11: Зачетные единицы | AL11: 5 семестр | AP11: 6 семестр | AT11: Зачетные единицы | AU11: 7 семестр | AY11: 8 семестр
E12: Экзамен | F12: Зачет | M12: Всего | P12: Лекции | Q12: Семинары, практические занятия | R12: Самостоятельная работа | T12: Часов аудиторных занятий в неделю | U12: 17 недель | X12: Часов аудиторных занятий в неделю | Y12: 17 недель | AC12: Часов аудиторных занятий в неделю | AD12: 17 недель | AG12: Часов аудиторных занятий в неделю | AH12: 17 недель | AL12: Часов аудиторных занятий в неделю | AM12: 17 недель | AP12: Часов аудиторных занятий в неделю | AQ12: 17 недель | AU12: Часов аудиторных занятий в неделю | AV12: 17 недель | AY12: Часов аудиторных занятий в неделю
U13: Лекции | V13: Семинары, практические занятия | W13: Самостоятельная работа | Y13: Лекции | Z13: Семинары, практические занятия | AA13: Самостоятельная работа | AD13: Лекции | AE13: Семинары, практические занятия | AF13: Самостоятельная работа | AH13: Лекции | AI13: Семинары, практические занятия | AJ13: Самостоятельная работа | AM13: Лекции | AN13: Семинары, практические занятия | AO13: Самостоятельная работа | AQ13: Лекции | AR13: Семинары, практические занятия | AS13: Самостоятельная работа | AV13: Лекции | AW13: Семинары, практические занятия | AX13: Самостоятельная работа | AZ13: Лекции | BA13: Семинары, практические занятия | BB13: Самостоятельная работа
A14: Б.1. | B14: Блок 1. Дисциплины (модули) | M14: =M15+M40 -> 207 | N14: =N15+N40 -> 6732 | O14: =O15+O40 -> 2636 | P14: =P15+P40 -> 728 | Q14: =Q15+Q40 -> 1908 | R14: =R15+R40 -> 4096 | S14: =S15+S40 -> 61 | T14: =T15+T40 -> 32 | ... BB14: =BB15+BB40 -> 0
A15: Б.1.1. | B15: Обязательная часть | M15: =M16+M27+M34 -> 102 | N15: =N16+N27+N34 -> 3672 | O15: =O16+O27+O34 -> 1456 | P15: =P16+P27+P34 -> 358 | Q15: =Q16+Q27+Q34 -> 1098 | R15: =R16+R27+R34 -> 2216 | S15: =S16+S27+S34 -> 46 | T15: =T16+T27+T34 -> 25 | ... BB15: =BB16+BB27+BB34 -> 0
A16: Б.1.1.1. | B16: Общегуманитарный цикл | M16: =SUM(M17:M26) -> 38 | N16: =SUM(N17:N26) -> 1368 | O16: =SUM(O17:O26) -> 650 | P16: =SUM(P17:P26) -> 130 | Q16: =SUM(Q17:Q26) -> 520 | R16: =SUM(R17:R26) -> 718 | S16: =SUM(S17:S26) -> 17 | T16: =SUM(T17:T26) -> 17 | ... BB16: =SUM(BB17:BB26) -> 0
A17: Б.1.1.1.2. | B17: Финансовый университет:история и современность | C17: ДАД | D17: =VLOOKUP(B17,'Матрица компетенций'!$A$4:$C$66,3,FALSE) -> УК-1 | F17: 1 | M17: =N17/36 -> 1 | N17: =O17+R17 -> 36 | O17: =P17+Q17 -> 16 | P17: =U17+Y17+AD17+AH17+AM17+AQ17+AV17+AZ17 -> 12 | Q17: =V17+Z17+AE17+AI17+AN17+AR17+AW17+BA17 -> 4 | R17: =W17+AA17+AF17+AJ17+AO17+AS17+AX17+BB17 -> 20 | S17: 1 | T17: 1 | U17: 12 | V17: 4 | W17: 20
A18: Б.1.1.1.11. | B18: История России | C18: ДГН | D18: =VLOOKUP(B18,'Матрица компетенций'!$A$4:$C$66,3,FALSE) -> УК-1, УК-15 | E18: 1 | I18: 1 | M18: =N18/36 -> 4 | N18: =O18+R18 -> 144 | O18: =P18+Q18 -> 86 | P18: =U18+Y18+AD18+AH18+AM18+AQ18+AV18+AZ18 -> 34 | Q18: =V18+Z18+AE18+AI18+AN18+AR18+AW18+BA18 -> 52 | R18: =W18+AA18+AF18+AJ18+AO18+AS18+AX18+BB18 -> 58 | S18: 4 | T18: 5 | U18: 34 | V18: 52 | W18: 58
A19: Б.1.1.1.1. | B19: Безопасность жизнедеятельности | C19: КБЖД | D19: =VLOOKUP(B19,'Матрица компетенций'!$A$4:$C$66,3,FALSE) -> УК-7 | F19: 1 | J19: 1 | M19: =N19/36 -> 2 | N19: =O19+R19 -> 72 | O19: =P19+Q19 -> 34 | P19: =U19+Y19+AD19+AH19+AM19+AQ19+AV19+AZ19 -> 16 | Q19: =V19+Z19+AE19+AI19+AN19+AR19+AW19+BA19 -> 18 | R19: =W19+AA19+AF19+AJ19+AO19+AS19+AX19+BB19 -> 38 | S19: 2 | T19: 2 | U19: 16 | V19: 18 | W19: 38
A20: Б.1.1.1.4. | B20: Физическая культура и спорт | C20: КФВ | D20: =VLOOKUP(B20,'Матрица компетенций'!$A$4:$C$66,3,FALSE) -> УК-6 | F20: 1 | M20: 2 | N20: =O20+R20 -> 72 | O20: =P20+Q20 -> 72 | P20: =U20+Y20+AD20+AH20+AM20+AQ20+AV20+AZ20 -> 2 | Q20: =V20+Z20+AE20+AI20+AN20+AR20+AW20+BA20 -> 70 | R20: =W20+AA20+AF20+AJ20+AO20+AS20+AX20+BB20 -> 0 | S20: 2 | T20: 4 | U20: 2 | V20: 70
A21: Б.1.1.1.3. | B21: Иностранный язык | C21: ДАЯиПК | D21: =VLOOKUP(B21,'Матрица компетенций'!$A$4:$C$66,3,FALSE) -> УК-3 | E21: 4 | F21: 1-3 | J21: 2,4 | M21: =N21/36 -> 9 | N21: =O21+R21 -> 324 | O21: =P21+Q21 -> 188 | P21: =U21+Y21+AD21+AH21+AM21+AQ21+AV21+AZ21 -> 0 | Q21: =V21+Z21+AE21+AI21+AN21+AR21+AW21+BA21 -> 188 | R21: =W21+AA21+AF21+AJ21+AO21+AS21+AX21+BB21 -> 136 | S21: 4 | T21: 3 | V21: 52 | W21: 36 | X21: 2 | Z21: 34 | AA21: 22 | AB21: 5 | AC21: 2 | AE21: 34 | AF21: 38 | AG21: 4 | AI21: 68 | AJ21: 40
B22: Иностранный язык в профессиональной сфере | C22: ДАЯиПК | D22: =VLOOKUP(B22,'Матрица компетенций'!$A$4:$C$66,3,FALSE) -> УК-2, УК-3 | E22: 6 | F22: 5 | J22: 6,5 | M22: =N22/36 -> 5 | N22: =O22+R22 -> 180 | O22: =P22+Q22 -> 68 | P22: =U22+Y22+AD22+AH22+AM22+AQ22+AV22+AZ22 -> 0 | Q22: =V22+Z22+AE22+AI22+AN22+AR22+AW22+BA22 -> 68 | R22: =W22+AA22+AF22+AJ22+AO22+AS22+AX22+BB22 -> 112 | AK22: 5 | AL22: 2 | AN22: 34 | AO22: 38 | AP22: 2 | AR22: 34 | AS22: 74
A23: Б.1.1.1.5. | B23: Философия | C23: ДГН | D23: =VLOOKUP(B23,'Матрица компетенций'!$A$4:$C$66,3,FALSE) -> УК-1, УК-9 | E23: 5 | K23: 5 | M23: =N23/36 -> 4 | N23: =O23+R23 -> 144 | O23: =P23+Q23 -> 68 | P23: =U23+Y23+AD23+AH23+AM23+AQ23+AV23+AZ23 -> 34 | Q23: =V23+Z23+AE23+AI23+AN23+AR23+AW23+BA23 -> 34 | R23: =W23+AA23+AF23+AJ23+AO23+AS23+AX23+BB23 -> 76 | AK23: 4 | AL23: 4 | AM23: 34 | AN23: 34 | AO23: 76
A24: Б.1.1.1.9. | B24: Информационное право | C24: ДМиПП | D24: =VLOOKUP(B24,'Матрица компетенций'!$A$4:$C$66,3,FALSE) -> УК-5, УК-14 | E24: 5 | J24: 5 | M24: =N24/36 -> 4 | N24: =O24+R24 -> 144 | O24: =P24+Q24 -> 50 | P24: =U24+Y24+AD24+AH24+AM24+AQ24+AV24+AZ24 -> 16 | Q24: =V24+Z24+AE24+AI24+AN24+AR24+AW24+BA24 -> 34 | R24: =W24+AA24+AF24+AJ24+AO24+AS24+AX24+BB24 -> 94 | AK24: 4 | AL24: 3 | AM24: 16 | AN24: 34 | AO24: 94
B25: Экономическая теория | C25: ДЭТ | D25: =VLOOKUP(B25,'Матрица компетенций'!$A$4:$C$66,3,FALSE) -> УК-13 | F25: 1 | J25: 1 | M25: =N25/36 -> 4 | N25: =O25+R25 -> 144 | O25: =P25+Q25 -> 34 | P25: =U25+Y25+AD25+AH25+AM25+AQ25+AV25+AZ25 -> 16 | Q25: =V25+Z25+AE25+AI25+AN25+AR25+AW25+BA25 -> 18 | R25: =W25+AA25+AF25+AJ25+AO25+AS25+AX25+BB25 -> 110 | S25: 4 | T25: 2 | U25: 16 | V25: 18 | W25: 110
B26: Основы деловой и публичной коммуникации | C26: ДИЯиМК | D26: =VLOOKUP(B26,'Матрица компетенций'!$A$4:$C$66,3,FALSE) -> УК-2, УК-3, УК-11 | F26: 7 | J26: 7 | M26: =N26/36 -> 3 | N26: =O26+R26 -> 108 | O26: =P26+Q26 -> 34 | P26: =U26+Y26+AD26+AH26+AM26+AQ26+AV26+AZ26 -> 0 | Q26: =V26+Z26+AE26+AI26+AN26+AR26+AW26+BA26 -> 34 | R26: =W26+AA26+AF26+AJ26+AO26+AS26+AX26+BB26 -> 74 | AT26: 3 | AU26: 2 | AW26: 34 | AX26: 74
A27: Б.1.1.2. | B27: Цикл математики и информатики | M27: =SUM(M28:M33) -> 28 | N27: =SUM(N28:N33) -> 1008 | O27: =SUM(O28:O33) -> 356 | P27: =SUM(P28:P33) -> 116 | Q27: =SUM(Q28:Q33) -> 240 | R27: =SUM(R28:R33) -> 652 | S27: =SUM(S28:S33) -> 13 | T27: =SUM(T28:T33) -> 4 | ... BB27: =SUM(BB28:BB33) -> 0
A28: Б.1.1.3.7. | B28: Введение в специальность | C28: ДАД | D28: =VLOOKUP(B28,'Матрица компетенций'!$A$4:$C$66,3,FALSE) -> УК-8, ПКН-3, ПКН-6 | F28: 1 | M28: =N28/36 -> 1 | N28: =O28+R28 -> 36 | O28: =P28+Q28 -> 6 | P28: =U28+Y28+AD28+AH28+AM28+AQ28+AV28+AZ28 -> 4 | Q28: =V28+Z28+AE28+AI28+AN28+AR28+AW28+BA28 -> 2 | R28: =W28+AA28+AF28+AJ28+AO28+AS28+AX28+BB28 -> 30 | S28: 1 | T28: 1 | U28: 4 | V28: 2 | W28: 30
A29: Б.1.1.2.3. | B29: Теория вероятностей и математическая статистика | C29: ДАД | D29: =VLOOKUP(B29,'Матрица компетенций'!$A$4:$C$66,3,FALSE) -> ПКН-1, ПКН-2 | E29: 3 | F29: 2 | J29: 3,2 | M29: =N29/36 -> 9 | N29: =O29+R29 -> 324 | O29: =P29+Q29 -> 100 | P29: =U29+Y29+AD29+AH29+AM29+AQ29+AV29+AZ29 -> 32 | Q29: =V29+Z29+AE29+AI29+AN29+AR29+AW29+BA29 -> 68 | R29: =W29+AA29+AF29+AJ29+AO29+AS29+AX29+BB29 -> 224 | S29: 4 | X29: 3 | Y29: 16 | Z29: 34 | AA29: 94 | AB29: 5 | AC29: 3 | AD29: 16 | AE29: 34 | AF29: 130
B30: Финансовая математика и ее приложения | C30: ДАД | D30: =VLOOKUP(B30,'Матрица компетенций'!$A$4:$C$66,3,FALSE) -> УК-12 | F30: 3 | J30: 3 | M30: =N30/36 -> 4 | N30: =O30+R30 -> 144 | O30: =P30+Q30 -> 50 | P30: =U30+Y30+AD30+AH30+AM30+AQ30+AV30+AZ30 -> 16 | Q30: =V30+Z30+AE30+AI30+AN30+AR30+AW30+BA30 -> 34 | R30: =W30+AA30+AF30+AJ30+AO30+AS30+AX30+BB30 -> 94 | AB30: 4 | AC30: 3 | AD30: 16 | AE30: 34 | AF30: 94
B31: Обработка данных и моделирование в табличном редакторе | C31: ДАД | D31: =VLOOKUP(B31,'Матрица компетенций'!$A$4:$C$66,3,FALSE) -> УК-4 | F31: 4 | J31: 4 | M31: =N31/36 -> 3 | N31: =O31+R31 -> 108 | O31: =P31+Q31 -> 50 | P31: =U31+Y31+AD31+AH31+AM31+AQ31+AV31+AZ31 -> 16 | Q31: =V31+Z31+AE31+AI31+AN31+AR31+AW31+BA31 -> 34 | R31: =W31+AA31+AF31+AJ31+AO31+AS31+AX31+BB31 -> 58 | AB31: 3 | AG31: 3 | AH31: 16 | AI31: 34 | AJ31: 58
B32: Математические модели микро- и макроэкономики | C32: ДМ | D32: =VLOOKUP(B32,'Матрица компетенций'!$A$4:$C$66,3,FALSE) -> УК-13, ПКН-1 | F32: 4 | J32: 4 | M32: =N32/36 -> 3 | N32: =O32+R32 -> 108 | O32: =P32+Q32 -> 50 | P32: =U32+Y32+AD32+AH32+AM32+AQ32+AV32+AZ32 -> 16 | Q32: =V32+Z32+AE32+AI32+AN32+AR32+AW32+BA32 -> 34 | R32: =W32+AA32+AF32+AJ32+AO32+AS32+AX32+BB32 -> 58 | AB32: 3 | AG32: 3 | AH32: 16 | AI32: 34 | AJ32: 58
A33: Б.1.1.2.1. | B33: Дискретная математика | C33: ДАД | D33: =VLOOKUP(B33,'Матрица компетенций'!$A$4:$C$66,3,FALSE) -> ПКН-1 | E33: 2 | F33: 1 | J33: 1,2 | M33: =N33/36 -> 8 | N33: =O33+R33 -> 288 | O33: =P33+Q33 -> 100 | P33: =U33+Y33+AD33+AH33+AM33+AQ33+AV33+AZ33 -> 32 | Q33: =V33+Z33+AE33+AI33+AN33+AR33+AW33+BA33 -> 68 | R33: =W33+AA33+AF33+AJ33+AO33+AS33+AX33+BB33 -> 188 | S33: 8 | T33: 3 | U33: 16 | V33: 34 | W33: 94 | X33: 3 | Y33: 16 | Z33: 34 | AA33: 94
A34: Б.1.1.3. | B34: Общепрофессиональный цикл | M34: =SUM(M35:M39) -> 36 | N34: =SUM(N35:N39) -> 1296 | O34: =SUM(O35:O39) -> 450 | P34: =SUM(P35:P39) -> 112 | Q34: =SUM(Q35:Q39) -> 338 | R34: =SUM(R35:R39) -> 846 | S34: =SUM(S35:S39) -> 16 | T34: =SUM(T35:T39) -> 4 | ... BB34: =SUM(BB35:BB39) -> 0
B35: Алгоритмы и структуры данных в языке Python* | C35: ДАД | D35: =VLOOKUP(B35,'Матрица компетенций'!$A$4:$C$66,3,FALSE) -> ПКН-2, ПКН-4 | E35: 1-2 | J35: 1,2 | M35: =N35/36 -> 8 | N35: =O35+R35 -> 288 | O35: =P35+Q35 -> 100 | P35: =U35+Y35+AD35+AH35+AM35+AQ35+AV35+AZ35 -> 32 | Q35: =V35+Z35+AE35+AI35+AN35+AR35+AW35+BA35 -> 68 | R35: =W35+AA35+AF35+AJ35+AO35+AS35+AX35+BB35 -> 188 | S35: 8 | T35: 3 | U35: 16 | V35: 34 | W35: 94 | X35: 3 | Y35: 16 | Z35: 34 | AA35: 94
B36: Практикум по программированию | C36: ДАД | D36: =VLOOKUP(B36,'Матрица компетенций'!$A$4:$C$66,3,FALSE) -> УК-10, ПКН-4 | F36: 1-4 | L36: 1-4 | M36: =N36/36 -> 8 | N36: =O36+R36 -> 288 | O36: =P36+Q36 -> 64 | P36: =U36+Y36+AD36+AH36+AM36+AQ36+AV36+AZ36 -> 0 | Q36: =V36+Z36+AE36+AI36+AN36+AR36+AW36+BA36 -> 64 | R36: =W36+AA36+AF36+AJ36+AO36+AS36+AX36+BB36 -> 224 | S36: 4 | T36: 1 | V36: 16 | W36: 56 | X36: 1 | Z36: 16 | AA36: 56 | AB36: 4 | AC36: 1 | AE36: 16 | AF36: 56 | AG36: 1 | AI36: 16 | AJ36: 56
A37: Б.1.2.2.4. | B37: Технологии обработки данных | C37: ДАД | D37: =VLOOKUP(B37,'Матрица компетенций'!$A$4:$C$66,3,FALSE) -> ПКН-2 | F37: 2 | J37: 2 | M37: =N37/36 -> 4 | N37: =O37+R37 -> 144 | O37: =P37+Q37 -> 50 | P37: =U37+Y37+AD37+AH37+AM37+AQ37+AV37+AZ37 -> 16 | Q37: =V37+Z37+AE37+AI37+AN37+AR37+AW37+BA37 -> 34 | R37: =W37+AA37+AF37+AJ37+AO37+AS37+AX37+BB37 -> 94 | S37: 4 | X37: 3 | Y37: 16 | Z37: 34 | AA37: 94
A38: Б.1.1.3.2. | B38: Системы управления базами данных* | C38: ДАД | D38: =VLOOKUP(B38,'Матрица компетенций'!$A$4:$C$66,3,FALSE) -> ПКН-4, ПКН-5 | E38: 4 | F38: 3 | J38: 3,4 | M38: =N38/36 -> 8 | N38: =O38+R38 -> 288 | O38: =P38+Q38 -> 136 | P38: =U38+Y38+AD38+AH38+AM38+AQ38+AV38+AZ38 -> 32 | Q38: =V38+Z38+AE38+AI38+AN38+AR38+AW38+BA38 -> 104 | R38: =W38+AA38+AF38+AJ38+AO38+AS38+AX38+BB38 -> 152 | AB38: 8 | AC38: 4 | AD38: 16 | AE38: 52 | AF38: 76 | AG38: 4 | AH38: 16 | AI38: 52 | AJ38: 76
A39: Б.1.1.3.3. | B39: Машинное обучение | C39: ДАД | D39: =VLOOKUP(B39,'Матрица компетенций'!$A$4:$C$66,3,FALSE) -> ПКН-2 | E39: 4 | F39: 3 | G39: 4 | J39: 3 | M39: =N39/36 -> 8 | N39: =O39+R39 -> 288 | O39: =P39+Q39 -> 100 | P39: =U39+Y39+AD39+AH39+AM39+AQ39+AV39+AZ39 -> 32 | Q39: =V39+Z39+AE39+AI39+AN39+AR39+AW39+BA39 -> 68 | R39: =W39+AA39+AF39+AJ39+AO39+AS39+AX39+BB39 -> 188 | AB39: 8 | AC39: 3 | AD39: 16 | AE39: 34 | AF39: 94 | AG39: 3 | AH39: 16 | AI39: 34 | AJ39: 94
A40: Б.1.2. | B40: Часть, формируемая участниками образовательных отношений | M40: =M41+M51 -> 105 | N40: =N41+N51 -> 3060 | O40: =O41+O51 -> 1180 | P40: =P41+P51 -> 370 | Q40: =Q41+Q51 -> 810 | R40: =R41+R51 -> 1880 | S40: =S41+S51 -> 15 | T40: =T41+T51 -> 7 | ... BB40: =BB41+BB51 -> 0
A41: Б.1.2.1. | B41: Общефакультетский (предпрофильный) цикл | M41: =SUM(M42:M50) -> 45 | N41: =SUM(N42:N46) -> 900 | O41: =SUM(O42:O46) -> 338 | P41: =SUM(P42:P46) -> 114 | Q41: =SUM(Q42:Q46) -> 224 | R41: =SUM(R42:R46) -> 562 | S41: =SUM(S42:S46) -> 15 | T41: =SUM(T42:T46) -> 7 | U41: =SUM(U42:U46) -> 32 | ... BB41: =SUM(BB42:BB46) -> 0
A42: Б.1.1.3.9. | B42: Алгебра и геометрия | C42: ДАД | D42: =VLOOKUP(B42,'Матрица компетенций'!$A$4:$C$66,3,FALSE) -> ПКН-2 | E42: 1 | J42: 1 | M42: =N42/36 -> 5 | N42: =O42+R42 -> 180 | O42: =P42+Q42 -> 68 | P42: =U42+Y42+AD42+AH42+AM42+AQ42+AV42+AZ42 -> 16 | Q42: =V42+Z42+AE42+AI42+AN42+AR42+AW42+BA42 -> 52 | R42: =W42+AA42+AF42+AJ42+AO42+AS42+AX42+BB42 -> 112 | S42: 5 | T42: 4 | U42: 16 | V42: 52 | W42: 112
...

Sheet Матрица компетенций
A1: МАТРИЦА КОМПЕТЕНЦИЙ
D2: УК-1 | E2: УК-2 | F2: УК-3 | G2: УК-4 | H2: УК-5 | I2: УК-6 | J2: УК-7 | K2: УК-8 | L2: УК-9 | M2: УК-10 | N2: УК-11 | O2: УК-12 | P2: УК-13 | Q2: УК-14 | R2: УК-15 | S2: ПКН-1 | T2: ПКН-2 | U2: ПКН-3 | V2: ПКН-4 | W2: ПКН-5 | X2: ПКН-6 | Y2: ПКП-1 | Z2: ПКП-2 | AA2: ПКП-3 | AB2: ПКП-4 | AC2: ПКП-5 | AD2: ПКП-6
D3: =COUNTA(D4:D44) -> 3 | E3: =COUNTA(E4:E44) -> 2 | F3: =COUNTA(F4:F44) -> 3 | G3: =COUNTA(G4:G44) -> 1 | H3: =COUNTA(H4:H44) -> 1 | I3: =COUNTA(I4:I44) -> 1 | J3: =COUNTA(J4:J44) -> 1 | K3: =COUNTA(K4:K44) -> 1 | ... AD3: =COUNTA(AD4:AD44) -> 1
A4: Финансовый университет:история и современность | B4: =COUNTA(D4:AD4) -> 1 | C4: =IFERROR(__xludf.DUMMYFUNCTION("TEXTJOIN("", "", 1, FILTER($D$2:$AD$2, D4:AD4=1))"),"УК-1") -> УК-1 | D4: 1
A5: История России | B5: =COUNTA(D5:AD5) -> 2 | C5: =IFERROR(__xludf.DUMMYFUNCTION("TEXTJOIN("", "", 1, FILTER($D$2:$AD$2, D5:AD5=1))"),"УК-1, УК-15") -> УК-1, УК-15 | D5: 1 | R5: 1
A6: Безопасность жизнедеятельности | B6: =COUNTA(D6:AD6) -> 1 | C6: =IFERROR(__xludf.DUMMYFUNCTION("TEXTJOIN("", "", 1, FILTER($D$2:$AD$2, D6:AD6=1))"),"УК-7") -> УК-7 | J6: 1
A7: Физическая культура и спорт | B7: =COUNTA(D7:AD7) -> 1 | C7: =IFERROR(__xludf.DUMMYFUNCTION("TEXTJOIN("", "", 1, FILTER($D$2:$AD$2, D7:AD7=1))"),"УК-6") -> УК-6 | I7: 1
A8: Иностранный язык | B8: =COUNTA(D8:AD8) -> 1 | C8: =IFERROR(__xludf.DUMMYFUNCTION("TEXTJOIN("", "", 1, FILTER($D$2:$AD$2, D8:AD8=1))"),"УК-3") -> УК-3 | F8: 1
A9: Иностранный язык в профессиональной сфере | B9: =COUNTA(D9:AD9) -> 2 | C9: =IFERROR(__xludf.DUMMYFUNCTION("TEXTJOIN("", "", 1, FILTER($D$2:$AD$2, D9:AD9=1))"),"УК-2, УК-3") -> УК-2, УК-3 | E9: 1 | F9: 1
A10: Философия | B10: =COUNTA(D10:AD10) -> 2 | C10: =IFERROR(__xludf.DUMMYFUNCTION("TEXTJOIN("", "", 1, FILTER($D$2:$AD$2, D10:AD10=1))"),"УК-1, УК-9") -> УК-1, УК-9 | D10: 1 | L10: 1
A11: Информационное право | B11: =COUNTA(D11:AD11) -> 2 | C11: =IFERROR(__xludf.DUMMYFUNCTION("TEXTJOIN("", "", 1, FILTER($D$2:$AD$2, D11:AD11=1))"),"УК-5, УК-14") -> УК-5, УК-14 | H11: 1 | Q11: 1
A12: Основы деловой и публичной коммуникации | B12: =COUNTA(D12:AD12) -> 3 | C12: =IFERROR(__xludf.DUMMYFUNCTION("TEXTJOIN("", "", 1, FILTER($D$2:$AD$2, D12:AD12=1))"),"УК-2, УК-3, УК-11") -> УК-2, УК-3, УК-11 | E12: 1 | F12: 1 | N12: 1
A13: Введение в специальность | B13: =COUNTA(D13:AD13) -> 3 | C13: =IFERROR(__xludf.DUMMYFUNCTION("TEXTJOIN("", "", 1, FILTER($D$2:$AD$2, D13:AD13=1))"),"УК-8, ПКН-3, ПКН-6") -> УК-8, ПКН-3, ПКН-6 | K13: 1 | U13: 1 | X13: 1
A14: Теория вероятностей и математическая статистика | B14: =COUNTA(D14:AD14) -> 2 | C14: =IFERROR(__xludf.DUMMYFUNCTION("TEXTJOIN("", "", 1, FILTER($D$2:$AD$2, D14:AD14=1))"),"ПКН-1, ПКН-2") -> ПКН-1, ПКН-2 | S14: 1 | T14: 1
A15: Алгоритмы и структуры данных в языке Python* | B15: =COUNTA(D15:AD15) -> 2 | C15: =IFERROR(__xludf.DUMMYFUNCTION("TEXTJOIN("", "", 1, FILTER($D$2:$AD$2, D15:AD15=1))"),"ПКН-2, ПКН-4") -> ПКН-2, ПКН-4 | T15: 1 | V15: 1
A16: Практикум по программированию | B16: =COUNTA(D16:AD16) -> 2 | C16: =IFERROR(__xludf.DUMMYFUNCTION("TEXTJOIN("", "", 1, FILTER($D$2:$AD$2, D16:AD16=1))"),"УК-10, ПКН-4") -> УК-10, ПКН-4 | M16: 1 | V16: 1
A17: Дискретная математика | B17: =COUNTA(D17:AD17) -> 1 | C17: =IFERROR(__xludf.DUMMYFUNCTION("TEXTJOIN("", "", 1, FILTER($D$2:$AD$2, D17:AD17=1))"),"ПКН-1") -> ПКН-1 | S17: 1
A18: Системы управления базами данных* | B18: =COUNTA(D18:AD18) -> 2 | C18: =IFERROR(__xludf.DUMMYFUNCTION("TEXTJOIN("", "", 1, FILTER($D$2:$AD$2, D18:AD18=1))"),"ПКН-4, ПКН-5") -> ПКН-4, ПКН-5 | V18: 1 | W18: 1
A19: Экономическая теория | B19: =COUNTA(D19:X19) -> 1 | C19: =IFERROR(__xludf.DUMMYFUNCTION("TEXTJOIN("", "", 1, FILTER($D$2:$AD$2, D19:AD19=1))"),"УК-13") -> УК-13 | P19: 1
A20: Финансы, деньги, кредит | B20: =COUNTA(D20:X20) -> 1 | C20: =IFERROR(__xludf.DUMMYFUNCTION("TEXTJOIN("", "", 1, FILTER($D$2:$AD$2, D20:AD20=1))"),"УК-13") -> УК-13 | P20: 1
A21: Финансовая математика и ее приложения | B21: =COUNTA(D21:X21) -> 1 | C21: =IFERROR(__xludf.DUMMYFUNCTION("TEXTJOIN("", "", 1, FILTER($D$2:$AD$2, D21:AD21=1))"),"УК-12") -> УК-12 | O21: 1
A22: Обработка данных и моделирование в табличном редакторе | B22: =COUNTA(D22:X22) -> 1 | C22: =IFERROR(__xludf.DUMMYFUNCTION("TEXTJOIN("", "", 1, FILTER($D$2:$AD$2, D22:AD22=1))"),"УК-4") -> УК-4 | G22: 1
A23: Математические модели микро- и макроэкономики | B23: =COUNTA(D23:X23) -> 2 | C23: =IFERROR(__xludf.DUMMYFUNCTION("TEXTJOIN("", "", 1, FILTER($D$2:$AD$2, D23:AD23=1))"),"УК-13, ПКН-1") -> УК-13, ПКН-1 | P23: 1 | S23: 1
A24: Машинное обучение | B24: =COUNTA(D24:X24) -> 1 | C24: =IFERROR(__xludf.DUMMYFUNCTION("TEXTJOIN("", "", 1, FILTER($D$2:$AD$2, D24:AD24=1))"),"ПКН-2") -> ПКН-2 | T24: 1
A25: Технологии обработки данных | B25: =COUNTA(D25:X25) -> 1 | C25: =IFERROR(__xludf.DUMMYFUNCTION("TEXTJOIN("", "", 1, FILTER($D$2:$AD$2, D25:AD25=1))"),"ПКН-2") -> ПКН-2 | T25: 1
A26: Алгебра и геометрия | B26: =COUNTA(D26:X26) -> 1 | C26: =IFERROR(__xludf.DUMMYFUNCTION("TEXTJOIN("", "", 1, FILTER($D$2:$AD$2, D26:AD26=1))"),"ПКН-2") -> ПКН-2 | T26: 1
A27: Математический анализ | B27: =COUNTA(D27:X27) -> 1 | C27: =IFERROR(__xludf.DUMMYFUNCTION("TEXTJOIN("", "", 1, FILTER($D$2:$AD$2, D27:AD27=1))"),"ПКН-2") -> ПКН-2 | T27: 1
A28: Дифференциальные уравнения | B28: =COUNTA(D28:X28) -> 1 | C28: =IFERROR(__xludf.DUMMYFUNCTION("TEXTJOIN("", "", 1, FILTER($D$2:$AD$2, D28:AD28=1))"),"ПКН-1") -> ПКН-1 | S28: 1
A29: Функциональный анализ | B29: =COUNTA(D29:X29) -> 1 | C29: =IFERROR(__xludf.DUMMYFUNCTION("TEXTJOIN("", "", 1, FILTER($D$2:$AD$2, D29:AD29=1))"),"ПКН-1") -> ПКН-1 | S29: 1
A30: Численные методы | B30: =COUNTA(D30:X30) -> 1 | C30: =IFERROR(__xludf.DUMMYFUNCTION("TEXTJOIN("", "", 1, FILTER($D$2:$AD$2, D30:AD30=1))"),"ПКН-1") -> ПКН-1 | S30: 1
A31: Математическое и имитационное моделирование | B31: =COUNTA(D31:X31) -> 1 | C31: =IFERROR(__xludf.DUMMYFUNCTION("TEXTJOIN("", "", 1, FILTER($D$2:$AD$2, D31:AD31=1))"),"ПКН-2") -> ПКН-2 | T31: 1
A32: Эконометрика | B32: =COUNTA(D32:X32) -> 1 | C32: =IFERROR(__xludf.DUMMYFUNCTION("TEXTJOIN("", "", 1, FILTER($D$2:$AD$2, D32:AD32=1))"),"ПКН-1") -> ПКН-1 | S32: 1
A33: Современные банковские продукты и услуги | B33: =COUNTA(D33:X33) -> 1 | C33: =IFERROR(__xludf.DUMMYFUNCTION("TEXTJOIN("", "", 1, FILTER($D$2:$AD$2, D33:AD33=1))"),"ПКН-6") -> ПКН-6 | X33: 1
A34: Технологии обработки больших данных | B34: =COUNTA(D34:X34) -> 1 | C34: =IFERROR(__xludf.DUMMYFUNCTION("TEXTJOIN("", "", 1, FILTER($D$2:$AD$2, D34:AD34=1))"),"ПКН-4") -> ПКН-4 | V34: 1
A35: Глубокое обучение | B35: =COUNTA(Y35:AD35) -> 2 | C35: =IFERROR(__xludf.DUMMYFUNCTION("TEXTJOIN("", "", 1, FILTER($D$2:$AD$2, D35:AD35=1))"),"ПКП-1, ПКП-5") -> ПКП-1, ПКП-5 | Y35: 1 | AC35: 1
A36: Обработка текстов на естественных языках | B36: =COUNTA(Y36:AD36) -> 2 | C36: =IFERROR(__xludf.DUMMYFUNCTION("TEXTJOIN("", "", 1, FILTER($D$2:$AD$2, D36:AD36=1))"),"ПКП-1, ПКП-5") -> ПКП-1, ПКП-5 | Y36: 1 | AC36: 1
A37: Рекомендательные системы и коллаборативная фильтрация | B37: =COUNTA(Y37:AD37) -> 1 | C37: =IFERROR(__xludf.DUMMYFUNCTION("TEXTJOIN("", "", 1, FILTER($D$2:$AD$2, D37:AD37=1))"),"ПКП-2") -> ПКП-2 | Z37: 1
A38: Семантические технологии | B38: =COUNTA(Y38:AD38) -> 1 | C38: =IFERROR(__xludf.DUMMYFUNCTION("TEXTJOIN("", "", 1, FILTER($D$2:$AD$2, D38:AD38=1))"),"ПКП-3") -> ПКП-3 | AA38: 1
A39: Прикладные задачи машинного обучения | B39: =COUNTA(Y39:AD39) -> 2 | C39: =IFERROR(__xludf.DUMMYFUNCTION("TEXTJOIN("", "", 1, FILTER($D$2:$AD$2, D39:AD39=1))"),"ПКП-1, ПКП-6") -> ПКП-1, ПКП-6 | Y39: 1 | AD39: 1
A40: Машинное зрение | B40: =COUNTA(Y40:AD40) -> 1 | C40: =IFERROR(__xludf.DUMMYFUNCTION("TEXTJOIN("", "", 1, FILTER($D$2:$AD$2, D40:AD40=1))"),"ПКП-1") -> ПКП-1 | Y40: 1
...

Sheet Описания компетенций
A1: ОПИСАНИЯ КОМПЕТЕНЦИЙ
A2: Имя | B2: Описание | D2: Год
A3: УК-1 | B3: Способность к восприятию межкультурного разнообразия общества, в социально-историческом, этическом и философских контекстах, анализу и мировоззренческой оценке происходящих процессов и закономерностей | D3: 2022
A4: УК-2 | B4: Способность применять нормы государственного языка Российской Федерации в устной и письменной речи в процессе личной и профессиональной коммуникаций | D4: 2022
A5: УК-3 | B5: Способность применять знания иностранного языка на уровне, достаточном для межличностного общения, учебной и профессиональной деятельности | D5: 2022
A6: УК-4 | B6: Способность использовать прикладное программное обеспечение при решении профессиональных задач | D6: 2022
A7: УК-5 | B7: Способность использовать основы правовых знаний в различных сферах деятельности | D7: 2022
A8: УК-6 | B8: Способность применять методы физической культуры для обеспечения полноценной социальной и профессиональной деятельности | D8: 2022
A9: УК-7 | B9: Способность создавать и поддерживать безопасные условия жизнедеятельности для сохранения природной среды, обеспечения устойчивого развития общества, владеть основными методами защиты от возможных последствий аварий, катастроф, стихийных бедствий и военных конфликтов | D9: 2022
A10: УК-8 | B10: Способность и готовность к самоорганизации, продолжению образования, к самообразованию на основе принципов образования в течение всей жизни | D10: 2022
A11: УК-9 | B11: Способность к индивидуальной и командной работе, социальному взаимодействию, соблюдению этических норм в межличностном профессиональном общении | D11: 2022
A12: УК-10 | B12: Способность осуществлять поиск, критически анализировать, обобщать и систематизировать информацию, использовать системный подход для решения поставленных задач | D12: 2022
A13: УК-11 | B13: Способность к постановке целей и задач исследований, выбору оптимальных путей и методов их достижения | D13: 2022
A14: УК-12 | B14: Способность использовать базовые дефектологические знания в социальной и профессиональной сферах | D14: 2022
... A29: ПКП-6 | B29: Способность выполнять сборку модулей и компонент программной реализации моделей машинного обучения и развертывания реализации моделей машинного обучения | D29: 2022
